Workbook
Name CondFocus: CondUpcoming*(T_Due<=TODAY()+6)
Name CondOverdue: InScope*(T_Status<>"Done")*ISNUMBER(T_Due)*(T_Due<TODAY())
Name CondUpcoming: InScope*(T_Status<>"Done")*ISNUMBER(T_Due)*(T_Due>=TODAY())
Name InScope: (T_Task<>"")*OwnerOK*StatusOK*YearOK
Name KpiDone: Dashboard!$D$7
Name KpiDueThisWeek: Dashboard!$M$7
Name KpiInProgress: Dashboard!$H$7
Name KpiOverdue: Dashboard!$J$7
Name KpiTotal: Dashboard!$B$7
Name OwnerList: Lists!$A$4:INDEX(Lists!$A$4:$A$34,COUNTIF(Lists!$A$4:$A$34,"?*"))
Name OwnerOK: ((SelOwner="(All)")+(SelOwner="")+(T_Owner=SelOwner))>0
Name OwnerRank: IF(T_Owner="",-1,COUNTIF(T_Owner,"<"&T_Owner))
Name RowNo: ROW(T_ID)-MIN(ROW(T_ID))+1
Name SelOwner: Dashboard!$C$4
Name SelStatus: Dashboard!$E$4
Name SelYear: Dashboard!$I$4
Name SortKey: IF(ISNUMBER(T_Due),T_Due,99999)+RowNo/100000
Name SortKeyView: IF(T_Status="Done",100000,0)+SortKey
Name StatusList: Lists!$C$4:$C$8
Name StatusOK: ((SelStatus="(All)")+(SelStatus="")+(T_Status=SelStatus))>0
Name T_Due: Tasks!$H$2:$H$43
Name T_ID: Tasks!$A$2:$A$43
Name T_Owner: Tasks!$C$2:$C$43
Name T_Status: Tasks!$E$2:$E$43
Name T_Task: Tasks!$B$2:$B$43
Name T_Year: Tasks!$J$2:$J$43
Name YearList: Lists!$E$4:INDEX(Lists!$E$4:$E$14,1+COUNT(Lists!$E$5:$E$14))
Name YearOK: ((SelYear="(All)")+(SelYear="")+(T_Year=SelYear))>0

Sheet Dashboard
B1: Work Tracker Dashboard
B2: ="As of "&TEXT(TODAY(),"ddd, mmm d, yyyy")&" | Pick an owner, status or year: the whole page follows." -> As of Fri, Oct 2, 2026 | Pick an owner, status or year: the whole page follows.
B4: Owner | C4: (All) | D4: Status | E4: (All) | H4: Year | I4: (All) | J4: =IF(AND(OR(SelOwner="(All)",SelOwner=""),OR(SelStatus="(All)",SelStatus=""),OR(SelYear="(All)",SelYear="")),"Showing all tasks","Filtered view: choose (All) to clear") -> Showing all tasks
B6: TOTAL TASKS | D6: DONE | H6: IN PROGRESS | J6: OVERDUE | M6: DUE THIS WEEK
B7: =SUMPRODUCT(InScope) -> 42 | D7: =SUMPRODUCT(InScope*(Tasks[Status]="Done")) -> 9 | H7: =SUMPRODUCT(InScope*(Tasks[Status]="In progress")) -> 15 | J7: =SUMPRODUCT(CondOverdue) -> 7 | M7: =SUMPRODUCT(CondFocus) -> 6
B10: This Week's Focus | D10: Not done, due in the next 7 days | H10: Next 5 due dates | J10: Not done, soonest first
B11: Due | C11: Task | D11: Owner | E11: Priority | F11: % done | H11: Due | I11: Task | J11: Owner | K11: Status | L11: Priority | M11: % done | N11: Days left | O11: Department
B12: =IF(Lists!$I4="","",INT(Lists!$H4)) -> 46297 | C12: =IF(Lists!$I4="","Nothing due in the next 7 days",INDEX(Tasks[Task],Lists!$I4)&"") -> Payroll calendar 2027 | D12: =IF(Lists!$I4="","",INDEX(Tasks[Owner],Lists!$I4)&"") -> Jordan M. | E12: =IF(Lists!$I4="","",INDEX(Tasks[Priority],Lists!$I4)&"") -> Medium | F12: =IF(Lists!$I4="","",INDEX(Tasks[% Complete],Lists!$I4)) -> 0.9 | H12: =IF(Lists!$M4="","",INT(Lists!$L4)) -> 46297 | I12: =IF(Lists!$M4="","Nothing coming up",INDEX(Tasks[Task],Lists!$M4)&"") -> Payroll calendar 2027 | J12: =IF(Lists!$M4="","",INDEX(Tasks[Owner],Lists!$M4)&"") -> Jordan M. | K12: =IF(Lists!$M4="","",INDEX(Tasks[Status],Lists!$M4)&"") -> In progress | L12: =IF(Lists!$M4="","",INDEX(Tasks[Priority],Lists!$M4)&"") -> Medium | M12: =IF(Lists!$M4="","",INDEX(Tasks[% Complete],Lists!$M4)) -> 0.9 | N12: =IF(Lists!$M4="","",INT(Lists!$L4)-TODAY()) -> 0 | O12: =IF(Lists!$M4="","",INDEX(Tasks[Department],Lists!$M4)&"") -> Finance
B13: =IF(Lists!$I5="","",INT(Lists!$H5)) -> 46298 | C13: =IF(Lists!$I5="","",INDEX(Tasks[Task],Lists!$I5)&"") -> Warehouse rack labels | D13: =IF(Lists!$I5="","",INDEX(Tasks[Owner],Lists!$I5)&"") -> Avery K. | E13: =IF(Lists!$I5="","",INDEX(Tasks[Priority],Lists!$I5)&"") -> Low | F13: =IF(Lists!$I5="","",INDEX(Tasks[% Complete],Lists!$I5)) -> 0.75 | H13: =IF(Lists!$M5="","",INT(Lists!$L5)) -> 46298 | I13: =IF(Lists!$M5="","",INDEX(Tasks[Task],Lists!$M5)&"") -> Warehouse rack labels | J13: =IF(Lists!$M5="","",INDEX(Tasks[Owner],Lists!$M5)&"") -> Avery K. | K13: =IF(Lists!$M5="","",INDEX(Tasks[Status],Lists!$M5)&"") -> In progress | L13: =IF(Lists!$M5="","",INDEX(Tasks[Priority],Lists!$M5)&"") -> Low | M13: =IF(Lists!$M5="","",INDEX(Tasks[% Complete],Lists!$M5)) -> 0.75 | N13: =IF(Lists!$M5="","",INT(Lists!$L5)-TODAY()) -> 1 | O13: =IF(Lists!$M5="","",INDEX(Tasks[Department],Lists!$M5)&"") -> Operations
B14: =IF(Lists!$I6="","",INT(Lists!$H6)) -> 46299 | C14: =IF(Lists!$I6="","",INDEX(Tasks[Task],Lists!$I6)&"") -> Quote follow-up calls | D14: =IF(Lists!$I6="","",INDEX(Tasks[Owner],Lists!$I6)&"") -> Casey L. | E14: =IF(Lists!$I6="","",INDEX(Tasks[Priority],Lists!$I6)&"") -> High | F14: =IF(Lists!$I6="","",INDEX(Tasks[% Complete],Lists!$I6)) -> 0 | H14: =IF(Lists!$M6="","",INT(Lists!$L6)) -> 46299 | I14: =IF(Lists!$M6="","",INDEX(Tasks[Task],Lists!$M6)&"") -> Quote follow-up calls | J14: =IF(Lists!$M6="","",INDEX(Tasks[Owner],Lists!$M6)&"") -> Casey L. | K14: =IF(Lists!$M6="","",INDEX(Tasks[Status],Lists!$M6)&"") -> Not started | L14: =IF(Lists!$M6="","",INDEX(Tasks[Priority],Lists!$M6)&"") -> High | M14: =IF(Lists!$M6="","",INDEX(Tasks[% Complete],Lists!$M6)) -> 0 | N14: =IF(Lists!$M6="","",INT(Lists!$L6)-TODAY()) -> 2 | O14: =IF(Lists!$M6="","",INDEX(Tasks[Department],Lists!$M6)&"") -> Sales
B15: =IF(Lists!$I7="","",INT(Lists!$H7)) -> 46300 | C15: =IF(Lists!$I7="","",INDEX(Tasks[Task],Lists!$I7)&"") -> Laptop refresh order | D15: =IF(Lists!$I7="","",INDEX(Tasks[Owner],Lists!$I7)&"") -> Riley P. | E15: =IF(Lists!$I7="","",INDEX(Tasks[Priority],Lists!$I7)&"") -> Medium | F15: =IF(Lists!$I7="","",INDEX(Tasks[% Complete],Lists!$I7)) -> 0.55 | H15: =IF(Lists!$M7="","",INT(Lists!$L7)) -> 46300 | I15: =IF(Lists!$M7="","",INDEX(Tasks[Task],Lists!$M7)&"") -> Laptop refresh order | J15: =IF(Lists!$M7="","",INDEX(Tasks[Owner],Lists!$M7)&"") -> Riley P. | K15: =IF(Lists!$M7="","",INDEX(Tasks[Status],Lists!$M7)&"") -> In progress | L15: =IF(Lists!$M7="","",INDEX(Tasks[Priority],Lists!$M7)&"") -> Medium | M15: =IF(Lists!$M7="","",INDEX(Tasks[% Complete],Lists!$M7)) -> 0.55 | N15: =IF(Lists!$M7="","",INT(Lists!$L7)-TODAY()) -> 3 | O15: =IF(Lists!$M7="","",INDEX(Tasks[Department],Lists!$M7)&"") -> IT
B16: =IF(Lists!$I8="","",INT(Lists!$H8)) -> 46302 | C16: =IF(Lists!$I8="","",INDEX(Tasks[Task],Lists!$I8)&"") -> Benefits enrollment memo | D16: =IF(Lists!$I8="","",INDEX(Tasks[Owner],Lists!$I8)&"") -> Morgan T. | E16: =IF(Lists!$I8="","",INDEX(Tasks[Priority],Lists!$I8)&"") -> High | F16: =IF(Lists!$I8="","",INDEX(Tasks[% Complete],Lists!$I8)) -> 0.35 | H16: =IF(Lists!$M8="","",INT(Lists!$L8)) -> 46302 | I16: =IF(Lists!$M8="","",INDEX(Tasks[Task],Lists!$M8)&"") -> Benefits enrollment memo | J16: =IF(Lists!$M8="","",INDEX(Tasks[Owner],Lists!$M8)&"") -> Morgan T. | K16: =IF(Lists!$M8="","",INDEX(Tasks[Status],Lists!$M8)&"") -> In progress | L16: =IF(Lists!$M8="","",INDEX(Tasks[Priority],Lists!$M8)&"") -> High | M16: =IF(Lists!$M8="","",INDEX(Tasks[% Complete],Lists!$M8)) -> 0.35 | N16: =IF(Lists!$M8="","",INT(Lists!$L8)-TODAY()) -> 5 | O16: =IF(Lists!$M8="","",INDEX(Tasks[Department],Lists!$M8)&"") -> HR
B17: =IF(Lists!$I9="","",INT(Lists!$H9)) -> 46303 | C17: =IF(Lists!$I9="","",INDEX(Tasks[Task],Lists!$I9)&"") -> Fleet insurance renewal | D17: =IF(Lists!$I9="","",INDEX(Tasks[Owner],Lists!$I9)&"") -> Taylor R. | E17: =IF(Lists!$I9="","",INDEX(Tasks[Priority],Lists!$I9)&"") -> High | F17: =IF(Lists!$I9="","",INDEX(Tasks[% Complete],Lists!$I9)) -> 0 | H17: =IF(SUMPRODUCT(CondUpcoming)>5,"+ "&(SUMPRODUCT(CondUpcoming)-5)&" more not shown","") -> + 21 more not shown
B18: =IF(Lists!$I10="","",INT(Lists!$H10)) | C18: =IF(Lists!$I10="","",INDEX(Tasks[Task],Lists!$I10)&"") | D18: =IF(Lists!$I10="","",INDEX(Tasks[Owner],Lists!$I10)&"") | E18: =IF(Lists!$I10="","",INDEX(Tasks[Priority],Lists!$I10)&"") | F18: =IF(Lists!$I10="","",INDEX(Tasks[% Complete],Lists!$I10))
B19: =IF(Lists!$I11="","",INT(Lists!$H11)) | C19: =IF(Lists!$I11="","",INDEX(Tasks[Task],Lists!$I11)&"") | D19: =IF(Lists!$I11="","",INDEX(Tasks[Owner],Lists!$I11)&"") | E19: =IF(Lists!$I11="","",INDEX(Tasks[Priority],Lists!$I11)&"") | F19: =IF(Lists!$I11="","",INDEX(Tasks[% Complete],Lists!$I11)) | H19: Tasks in view | J19: ="Open tasks first, then by due date | "&KpiTotal&" match the filters" -> Open tasks first, then by due date | 42 match the filters
B20: =IF(KpiDueThisWeek>8,"+ "&(KpiDueThisWeek-8)&" more not shown","") | H20: Due | I20: Task | J20: Owner | K20: Status | L20: Priority | M20: % done | N20: Flag | O20: Department
H21: =IF(Lists!$Q4="","",IF(MOD(INT(Lists!$P4),100000)=99999,"",MOD(INT(Lists!$P4),100000))) -> 46282 | I21: =IF(Lists!$Q4="","No tasks match these filters",INDEX(Tasks[Task],Lists!$Q4)&"") -> Trade show booth order | J21: =IF(Lists!$Q4="","",INDEX(Tasks[Owner],Lists!$Q4)&"") -> Casey L. | K21: =IF(Lists!$Q4="","",INDEX(Tasks[Status],Lists!$Q4)&"") -> Blocked | L21: =IF(Lists!$Q4="","",INDEX(Tasks[Priority],Lists!$Q4)&"") -> Medium | M21: =IF(Lists!$Q4="","",INDEX(Tasks[% Complete],Lists!$Q4)) -> 0.3 | N21: =IF(OR(Lists!$Q4="",H21="",K21="Done"),"",IF(H21<TODAY(),"OVERDUE",IF(H21<=TODAY()+6,"This week",""))) -> OVERDUE | O21: =IF(Lists!$Q4="","",INDEX(Tasks[Department],Lists!$Q4)&"") -> Sales
B22: Progress by owner | D22: Follows the filters | H22: =IF(Lists!$Q5="","",IF(MOD(INT(Lists!$P5),100000)=99999,"",MOD(INT(Lists!$P5),100000))) -> 46285 | I22: =IF(Lists!$Q5="","",INDEX(Tasks[Task],Lists!$Q5)&"") -> Vendor contract renewal | J22: =IF(Lists!$Q5="","",INDEX(Tasks[Owner],Lists!$Q5)&"") -> Taylor R. | K22: =IF(Lists!$Q5="","",INDEX(Tasks[Status],Lists!$Q5)&"") -> In progress | L22: =IF(Lists!$Q5="","",INDEX(Tasks[Priority],Lists!$Q5)&"") -> High | M22: =IF(Lists!$Q5="","",INDEX(Tasks[% Complete],Lists!$Q5)) -> 0.7 | N22: =IF(OR(Lists!$Q5="",H22="",K22="Done"),"",IF(H22<TODAY(),"OVERDUE",IF(H22<=TODAY()+6,"This week",""))) -> OVERDUE | O22: =IF(Lists!$Q5="","",INDEX(Tasks[Department],Lists!$Q5)&"") -> Operations
B23: Owner | C23: Average % done | D23: Tasks | E23: Done | F23: Overdue | H23: =IF(Lists!$Q6="","",IF(MOD(INT(Lists!$P6),100000)=99999,"",MOD(INT(Lists!$P6),100000))) -> 46289 | I23: =IF(Lists!$Q6="","",INDEX(Tasks[Task],Lists!$Q6)&"") -> Customer survey mailing | J23: =IF(Lists!$Q6="","",INDEX(Tasks[Owner],Lists!$Q6)&"") -> Casey L. | K23: =IF(Lists!$Q6="","",INDEX(Tasks[Status],Lists!$Q6)&"") -> In progress | L23: =IF(Lists!$Q6="","",INDEX(Tasks[Priority],Lists!$Q6)&"") -> Medium | M23: =IF(Lists!$Q6="","",INDEX(Tasks[% Complete],Lists!$Q6)) -> 0.6 | N23: =IF(OR(Lists!$Q6="",H23="",K23="Done"),"",IF(H23<TODAY(),"OVERDUE",IF(H23<=TODAY()+6,"This week",""))) -> OVERDUE | O23: =IF(Lists!$Q6="","",INDEX(Tasks[Department],Lists!$Q6)&"") -> Sales
B24: =IF(Lists!$A5="","",Lists!$A5) -> Avery K. | C24: =IF(OR(B24="",D24=0),"",SUMPRODUCT(InScope*(Tasks[Owner]=B24)*Tasks[% Complete])/D24) -> 0.31 | D24: =IF(B24="","",SUMPRODUCT(InScope*(Tasks[Owner]=B24))) -> 5 | E24: =IF(B24="","",SUMPRODUCT(InScope*(Tasks[Owner]=B24)*(Tasks[Status]="Done"))) -> 0 | F24: =IF(B24="","",SUMPRODUCT(CondOverdue*(Tasks[Owner]=B24))) -> 1 | H24: =IF(Lists!$Q7="","",IF(MOD(INT(Lists!$P7),100000)=99999,"",MOD(INT(Lists!$P7),100000))) -> 46291 | I24: =IF(Lists!$Q7="","",INDEX(Tasks[Task],Lists!$Q7)&"") -> Backup system test | J24: =IF(Lists!$Q7="","",INDEX(Tasks[Owner],Lists!$Q7)&"") -> Riley P. | K24: =IF(Lists!$Q7="","",INDEX(Tasks[Status],Lists!$Q7)&"") -> Blocked | L24: =IF(Lists!$Q7="","",INDEX(Tasks[Priority],Lists!$Q7)&"") -> High | M24: =IF(Lists!$Q7="","",INDEX(Tasks[% Complete],Lists!$Q7)) -> 0.4 | N24: =IF(OR(Lists!$Q7="",H24="",K24="Done"),"",IF(H24<TODAY(),"OVERDUE",IF(H24<=TODAY()+6,"This week",""))) -> OVERDUE | O24: =IF(Lists!$Q7="","",INDEX(Tasks[Department],Lists!$Q7)&"") -> IT
B25: =IF(Lists!$A6="","",Lists!$A6) -> Casey L. | C25: =IF(OR(B25="",D25=0),"",SUMPRODUCT(InScope*(Tasks[Owner]=B25)*Tasks[% Complete])/D25) -> 0.37777778 | D25: =IF(B25="","",SUMPRODUCT(InScope*(Tasks[Owner]=B25))) -> 9 | E25: =IF(B25="","",SUMPRODUCT(InScope*(Tasks[Owner]=B25)*(Tasks[Status]="Done"))) -> 2 | F25: =IF(B25="","",SUMPRODUCT(CondOverdue*(Tasks[Owner]=B25))) -> 2 | H25: =IF(Lists!$Q8="","",IF(MOD(INT(Lists!$P8),100000)=99999,"",MOD(INT(Lists!$P8),100000))) -> 46293 | I25: =IF(Lists!$Q8="","",INDEX(Tasks[Task],Lists!$Q8)&"") -> Expense policy update | J25: =IF(Lists!$Q8="","",INDEX(Tasks[Owner],Lists!$Q8)&"") -> Jordan M. | K25: =IF(Lists!$Q8="","",INDEX(Tasks[Status],Lists!$Q8)&"") -> In progress | L25: =IF(Lists!$Q8="","",INDEX(Tasks[Priority],Lists!$Q8)&"") -> Medium | M25: =IF(Lists!$Q8="","",INDEX(Tasks[% Complete],Lists!$Q8)) -> 0.8 | N25: =IF(OR(Lists!$Q8="",H25="",K25="Done"),"",IF(H25<TODAY(),"OVERDUE",IF(H25<=TODAY()+6,"This week",""))) -> OVERDUE | O25: =IF(Lists!$Q8="","",INDEX(Tasks[Department],Lists!$Q8)&"") -> Finance
B26: =IF(Lists!$A7="","",Lists!$A7) -> Jordan M. | C26: =IF(OR(B26="",D26=0),"",SUMPRODUCT(InScope*(Tasks[Owner]=B26)*Tasks[% Complete])/D26) -> 0.51875 | D26: =IF(B26="","",SUMPRODUCT(InScope*(Tasks[Owner]=B26))) -> 8 | E26: =IF(B26="","",SUMPRODUCT(InScope*(Tasks[Owner]=B26)*(Tasks[Status]="Done"))) -> 2 | F26: =IF(B26="","",SUMPRODUCT(CondOverdue*(Tasks[Owner]=B26))) -> 1 | H26: =IF(Lists!$Q9="","",IF(MOD(INT(Lists!$P9),100000)=99999,"",MOD(INT(Lists!$P9),100000))) -> 46295 | I26: =IF(Lists!$Q9="","",INDEX(Tasks[Task],Lists!$Q9)&"") -> Safety training sign-off | J26: =IF(Lists!$Q9="","",INDEX(Tasks[Owner],Lists!$Q9)&"") -> Morgan T. | K26: =IF(Lists!$Q9="","",INDEX(Tasks[Status],Lists!$Q9)&"") -> Not started | L26: =IF(Lists!$Q9="","",INDEX(Tasks[Priority],Lists!$Q9)&"") -> High | M26: =IF(Lists!$Q9="","",INDEX(Tasks[% Complete],Lists!$Q9)) -> 0 | N26: =IF(OR(Lists!$Q9="",H26="",K26="Done"),"",IF(H26<TODAY(),"OVERDUE",IF(H26<=TODAY()+6,"This week",""))) -> OVERDUE | O26: =IF(Lists!$Q9="","",INDEX(Tasks[Department],Lists!$Q9)&"") -> HR
B27: =IF(Lists!$A8="","",Lists!$A8) -> Morgan T. | C27: =IF(OR(B27="",D27=0),"",SUMPRODUCT(InScope*(Tasks[Owner]=B27)*Tasks[% Complete])/D27) -> 0.35714286 | D27: =IF(B27="","",SUMPRODUCT(InScope*(Tasks[Owner]=B27))) -> 7 | E27: =IF(B27="","",SUMPRODUCT(InScope*(Tasks[Owner]=B27)*(Tasks[Status]="Done"))) -> 2 | F27: =IF(B27="","",SUMPRODUCT(CondOverdue*(Tasks[Owner]=B27))) -> 1 | H27: =IF(Lists!$Q10="","",IF(MOD(INT(Lists!$P10),100000)=99999,"",MOD(INT(Lists!$P10),100000))) -> 46296 | I27: =IF(Lists!$Q10="","",INDEX(Tasks[Task],Lists!$Q10)&"") -> Forklift inspection | J27: =IF(Lists!$Q10="","",INDEX(Tasks[Owner],Lists!$Q10)&"") -> Avery K. | K27: =IF(Lists!$Q10="","",INDEX(Tasks[Status],Lists!$Q10)&"") -> In progress | L27: =IF(Lists!$Q10="","",INDEX(Tasks[Priority],Lists!$Q10)&"") -> High | M27: =IF(Lists!$Q10="","",INDEX(Tasks[% Complete],Lists!$Q10)) -> 0.5 | N27: =IF(OR(Lists!$Q10="",H27="",K27="Done"),"",IF(H27<TODAY(),"OVERDUE",IF(H27<=TODAY()+6,"This week",""))) -> OVERDUE | O27: =IF(Lists!$Q10="","",INDEX(Tasks[Department],Lists!$Q10)&"") -> Operations
B28: =IF(Lists!$A9="","",Lists!$A9) -> Riley P. | C28: =IF(OR(B28="",D28=0),"",SUMPRODUCT(InScope*(Tasks[Owner]=B28)*Tasks[% Complete])/D28) -> 0.41875 | D28: =IF(B28="","",SUMPRODUCT(InScope*(Tasks[Owner]=B28))) -> 8 | E28: =IF(B28="","",SUMPRODUCT(InScope*(Tasks[Owner]=B28)*(Tasks[Status]="Done"))) -> 2 | F28: =IF(B28="","",SUMPRODUCT(CondOverdue*(Tasks[Owner]=B28))) -> 1 | H28: =IF(Lists!$Q11="","",IF(MOD(INT(Lists!$P11),100000)=99999,"",MOD(INT(Lists!$P11),100000))) -> 46297 | I28: =IF(Lists!$Q11="","",INDEX(Tasks[Task],Lists!$Q11)&"") -> Payroll calendar 2027 | J28: =IF(Lists!$Q11="","",INDEX(Tasks[Owner],Lists!$Q11)&"") -> Jordan M. | K28: =IF(Lists!$Q11="","",INDEX(Tasks[Status],Lists!$Q11)&"") -> In progress | L28: =IF(Lists!$Q11="","",INDEX(Tasks[Priority],Lists!$Q11)&"") -> Medium | M28: =IF(Lists!$Q11="","",INDEX(Tasks[% Complete],Lists!$Q11)) -> 0.9 | N28: =IF(OR(Lists!$Q11="",H28="",K28="Done"),"",IF(H28<TODAY(),"OVERDUE",IF(H28<=TODAY()+6,"This week",""))) -> This week | O28: =IF(Lists!$Q11="","",INDEX(Tasks[Department],Lists!$Q11)&"") -> Finance
B29: =IF(Lists!$A10="","",Lists!$A10) -> Taylor R. | C29: =IF(OR(B29="",D29=0),"",SUMPRODUCT(InScope*(Tasks[Owner]=B29)*Tasks[% Complete])/D29) -> 0.42 | D29: =IF(B29="","",SUMPRODUCT(InScope*(Tasks[Owner]=B29))) -> 5 | E29: =IF(B29="","",SUMPRODUCT(InScope*(Tasks[Owner]=B29)*(Tasks[Status]="Done"))) -> 1 | F29: =IF(B29="","",SUMPRODUCT(CondOverdue*(Tasks[Owner]=B29))) -> 1 | H29: =IF(Lists!$Q12="","",IF(MOD(INT(Lists!$P12),100000)=99999,"",MOD(INT(Lists!$P12),100000))) -> 46298 | I29: =IF(Lists!$Q12="","",INDEX(Tasks[Task],Lists!$Q12)&"") -> Warehouse rack labels | J29: =IF(Lists!$Q12="","",INDEX(Tasks[Owner],Lists!$Q12)&"") -> Avery K. | K29: =IF(Lists!$Q12="","",INDEX(Tasks[Status],Lists!$Q12)&"") -> In progress | L29: =IF(Lists!$Q12="","",INDEX(Tasks[Priority],Lists!$Q12)&"") -> Low | M29: =IF(Lists!$Q12="","",INDEX(Tasks[% Complete],Lists!$Q12)) -> 0.75 | N29: =IF(OR(Lists!$Q12="",H29="",K29="Done"),"",IF(H29<TODAY(),"OVERDUE",IF(H29<=TODAY()+6,"This week",""))) -> This week | O29: =IF(Lists!$Q12="","",INDEX(Tasks[Department],Lists!$Q12)&"") -> Operations
B30: =IF(Lists!$A11="","",Lists!$A11) | C30: =IF(OR(B30="",D30=0),"",SUMPRODUCT(InScope*(Tasks[Owner]=B30)*Tasks[% Complete])/D30) | D30: =IF(B30="","",SUMPRODUCT(InScope*(Tasks[Owner]=B30))) | E30: =IF(B30="","",SUMPRODUCT(InScope*(Tasks[Owner]=B30)*(Tasks[Status]="Done"))) | F30: =IF(B30="","",SUMPRODUCT(CondOverdue*(Tasks[Owner]=B30))) | H30: =IF(Lists!$Q13="","",IF(MOD(INT(Lists!$P13),100000)=99999,"",MOD(INT(Lists!$P13),100000))) -> 46299 | I30: =IF(Lists!$Q13="","",INDEX(Tasks[Task],Lists!$Q13)&"") -> Quote follow-up calls | J30: =IF(Lists!$Q13="","",INDEX(Tasks[Owner],Lists!$Q13)&"") -> Casey L. | K30: =IF(Lists!$Q13="","",INDEX(Tasks[Status],Lists!$Q13)&"") -> Not started | L30: =IF(Lists!$Q13="","",INDEX(Tasks[Priority],Lists!$Q13)&"") -> High | M30: =IF(Lists!$Q13="","",INDEX(Tasks[% Complete],Lists!$Q13)) -> 0 | N30: =IF(OR(Lists!$Q13="",H30="",K30="Done"),"",IF(H30<TODAY(),"OVERDUE",IF(H30<=TODAY()+6,"This week",""))) -> This week | O30: =IF(Lists!$Q13="","",INDEX(Tasks[Department],Lists!$Q13)&"") -> Sales
B31: =IF(Lists!$A12="","",Lists!$A12) | C31: =IF(OR(B31="",D31=0),"",SUMPRODUCT(InScope*(Tasks[Owner]=B31)*Tasks[% Complete])/D31) | D31: =IF(B31="","",SUMPRODUCT(InScope*(Tasks[Owner]=B31))) | E31: =IF(B31="","",SUMPRODUCT(InScope*(Tasks[Owner]=B31)*(Tasks[Status]="Done"))) | F31: =IF(B31="","",SUMPRODUCT(CondOverdue*(Tasks[Owner]=B31))) | H31: =IF(Lists!$Q14="","",IF(MOD(INT(Lists!$P14),100000)=99999,"",MOD(INT(Lists!$P14),100000))) -> 46300 | I31: =IF(Lists!$Q14="","",INDEX(Tasks[Task],Lists!$Q14)&"") -> Laptop refresh order | J31: =IF(Lists!$Q14="","",INDEX(Tasks[Owner],Lists!$Q14)&"") -> Riley P. | K31: =IF(Lists!$Q14="","",INDEX(Tasks[Status],Lists!$Q14)&"") -> In progress | L31: =IF(Lists!$Q14="","",INDEX(Tasks[Priority],Lists!$Q14)&"") -> Medium | M31: =IF(Lists!$Q14="","",INDEX(Tasks[% Complete],Lists!$Q14)) -> 0.55 | N31: =IF(OR(Lists!$Q14="",H31="",K31="Done"),"",IF(H31<TODAY(),"OVERDUE",IF(H31<=TODAY()+6,"This week",""))) -> This week | O31: =IF(Lists!$Q14="","",INDEX(Tasks[Department],Lists!$Q14)&"") -> IT
B32: =IF(COUNTIF(Lists!$A$5:$A$34,"?*")>8,"+ "&(COUNTIF(Lists!$A$5:$A$34,"?*")-8)&" more owners not shown","") | H32: =IF(Lists!$Q15="","",IF(MOD(INT(Lists!$P15),100000)=99999,"",MOD(INT(Lists!$P15),100000))) -> 46302 | I32: =IF(Lists!$Q15="","",INDEX(Tasks[Task],Lists!$Q15)&"") -> Benefits enrollment memo | J32: =IF(Lists!$Q15="","",INDEX(Tasks[Owner],Lists!$Q15)&"") -> Morgan T. | K32: =IF(Lists!$Q15="","",INDEX(Tasks[Status],Lists!$Q15)&"") -> In progress | L32: =IF(Lists!$Q15="","",INDEX(Tasks[Priority],Lists!$Q15)&"") -> High | M32: =IF(Lists!$Q15="","",INDEX(Tasks[% Complete],Lists!$Q15)) -> 0.35 | N32: =IF(OR(Lists!$Q15="",H32="",K32="Done"),"",IF(H32<TODAY(),"OVERDUE",IF(H32<=TODAY()+6,"This week",""))) -> This week | O32: =IF(Lists!$Q15="","",INDEX(Tasks[Department],Lists!$Q15)&"") -> HR
H33: =IF(Lists!$Q16="","",IF(MOD(INT(Lists!$P16),100000)=99999,"",MOD(INT(Lists!$P16),100000))) -> 46303 | I33: =IF(Lists!$Q16="","",INDEX(Tasks[Task],Lists!$Q16)&"") -> Fleet insurance renewal | J33: =IF(Lists!$Q16="","",INDEX(Tasks[Owner],Lists!$Q16)&"") -> Taylor R. | K33: =IF(Lists!$Q16="","",INDEX(Tasks[Status],Lists!$Q16)&"") -> Not started | L33: =IF(Lists!$Q16="","",INDEX(Tasks[Priority],Lists!$Q16)&"") -> High | M33: =IF(Lists!$Q16="","",INDEX(Tasks[% Complete],Lists!$Q16)) -> 0 | N33: =IF(OR(Lists!$Q16="",H33="",K33="Done"),"",IF(H33<TODAY(),"OVERDUE",IF(H33<=TODAY()+6,"This week",""))) -> This week | O33: =IF(Lists!$Q16="","",INDEX(Tasks[Department],Lists!$Q16)&"") -> Operations
H34: =IF(Lists!$Q17="","",IF(MOD(INT(Lists!$P17),100000)=99999,"",MOD(INT(Lists!$P17),100000))) -> 46304 | I34: =IF(Lists!$Q17="","",INDEX(Tasks[Task],Lists!$Q17)&"") -> Budget draft for 2027 | J34: =IF(Lists!$Q17="","",INDEX(Tasks[Owner],Lists!$Q17)&"") -> Jordan M. | K34: =IF(Lists!$Q17="","",INDEX(Tasks[Status],Lists!$Q17)&"") -> In progress | L34: =IF(Lists!$Q17="","",INDEX(Tasks[Priority],Lists!$Q17)&"") -> High | M34: =IF(Lists!$Q17="","",INDEX(Tasks[% Complete],Lists!$Q17)) -> 0.45 | N34: =IF(OR(Lists!$Q17="",H34="",K34="Done"),"",IF(H34<TODAY(),"OVERDUE",IF(H34<=TODAY()+6,"This week",""))) | O34: =IF(Lists!$Q17="","",INDEX(Tasks[Department],Lists!$Q17)&"") -> Finance
H35: =IF(Lists!$Q18="","",IF(MOD(INT(Lists!$P18),100000)=99999,"",MOD(INT(Lists!$P18),100000))) -> 46305 | I35: =IF(Lists!$Q18="","",INDEX(Tasks[Task],Lists!$Q18)&"") -> Website contact form fix | J35: =IF(Lists!$Q18="","",INDEX(Tasks[Owner],Lists!$Q18)&"") -> Riley P. | K35: =IF(Lists!$Q18="","",INDEX(Tasks[Status],Lists!$Q18)&"") -> Not started | L35: =IF(Lists!$Q18="","",INDEX(Tasks[Priority],Lists!$Q18)&"") -> Medium | M35: =IF(Lists!$Q18="","",INDEX(Tasks[% Complete],Lists!$Q18)) -> 0 | N35: =IF(OR(Lists!$Q18="",H35="",K35="Done"),"",IF(H35<TODAY(),"OVERDUE",IF(H35<=TODAY()+6,"This week",""))) | O35: =IF(Lists!$Q18="","",INDEX(Tasks[Department],Lists!$Q18)&"") -> IT
H36: =IF(KpiTotal>15,"+ "&(KpiTotal-15)&" more not shown","") -> + 27 more not shown

Sheet Tasks
A1: ID | B1: Task | C1: Owner | D1: Department | E1: Status | F1: Priority | G1: Start | H1: Due | I1: % Complete | J1: Year | K1: Notes
A2: T-001 | B2: Renew office lease | C2: Taylor R. | D2: Operations | E2: Done | F2: High | G2: 46237 | H2: 46262 | I2: 1 | J2: =IF(Tasks[[#This Row],[Due]]="","",YEAR(Tasks[[#This Row],[Due]])) -> 2026 | K2: Signed for 3 years
A3: T-002 | B3: Q3 month-end checklist | C3: Jordan M. | D3: Finance | E3: Done | F3: High | G3: 46252 | H3: 46269 | I3: 1 | J3: =IF(Tasks[[#This Row],[Due]]="","",YEAR(Tasks[[#This Row],[Due]])) -> 2026
A4: T-003 | B4: Update price list | C4: Casey L. | D4: Sales | E4: Done | F4: Medium | G4: 46257 | H4: 46276 | I4: 1 | J4: =IF(Tasks[[#This Row],[Due]]="","",YEAR(Tasks[[#This Row],[Due]])) -> 2026 | K4: Sent to all reps
A5: T-004 | B5: Replace front-desk PC | C5: Riley P. | D5: IT | E5: Done | F5: Low | G5: 46267 | H5: 46283 | I5: 1 | J5: =IF(Tasks[[#This Row],[Due]]="","",YEAR(Tasks[[#This Row],[Due]])) -> 2026
A6: T-005 | B6: New-hire paperwork review | C6: Morgan T. | D6: HR | E6: Done | F6: Medium | G6: 46272 | H6: 46288 | I6: 1 | J6: =IF(Tasks[[#This Row],[Due]]="","",YEAR(Tasks[[#This Row],[Due]])) -> 2026
A7: T-006 | B7: Vendor contract renewal | C7: Taylor R. | D7: Operations | E7: In progress | F7: High | G7: 46267 | H7: 46285 | I7: 0.7 | J7: =IF(Tasks[[#This Row],[Due]]="","",YEAR(Tasks[[#This Row],[Due]])) -> 2026 | K7: Waiting on vendor redline
A8: T-007 | B8: Customer survey mailing | C8: Casey L. | D8: Sales | E8: In progress | F8: Medium | G8: 46269 | H8: 46289 | I8: 0.6 | J8: =IF(Tasks[[#This Row],[Due]]="","",YEAR(Tasks[[#This Row],[Due]])) -> 2026
A9: T-008 | B9: Backup system test | C9: Riley P. | D9: IT | E9: Blocked | F9: High | G9: 46277 | H9: 46291 | I9: 0.4 | J9: =IF(Tasks[[#This Row],[Due]]="","",YEAR(Tasks[[#This Row],[Due]])) -> 2026 | K9: Needs a new drive
A10: T-009 | B10: Expense policy update | C10: Jordan M. | D10: Finance | E10: In progress | F10: Medium | G10: 46276 | H10: 46293 | I10: 0.8 | J10: =IF(Tasks[[#This Row],[Due]]="","",YEAR(Tasks[[#This Row],[Due]])) -> 2026
A11: T-010 | B11: Safety training sign-off | C11: Morgan T. | D11: HR | E11: Not started | F11: High | G11: 46287 | H11: 46295 | I11: 0 | J11: =IF(Tasks[[#This Row],[Due]]="","",YEAR(Tasks[[#This Row],[Due]])) -> 2026
A12: T-011 | B12: Forklift inspection | C12: Avery K. | D12: Operations | E12: In progress | F12: High | G12: 46288 | H12: 46296 | I12: 0.5 | J12: =IF(Tasks[[#This Row],[Due]]="","",YEAR(Tasks[[#This Row],[Due]])) -> 2026
A13: T-012 | B13: Trade show booth order | C13: Casey L. | D13: Sales | E13: Blocked | F13: Medium | G13: 46279 | H13: 46282 | I13: 0.3 | J13: =IF(Tasks[[#This Row],[Due]]="","",YEAR(Tasks[[#This Row],[Due]])) -> 2026 | K13: Supplier out of stock
A14: T-013 | B14: Payroll calendar 2027 | C14: Jordan M. | D14: Finance | E14: In progress | F14: Medium | G14: 46290 | H14: 46297 | I14: 0.9 | J14: =IF(Tasks[[#This Row],[Due]]="","",YEAR(Tasks[[#This Row],[Due]])) -> 2026
A15: T-014 | B15: Warehouse rack labels | C15: Avery K. | D15: Operations | E15: In progress | F15: Low | G15: 46291 | H15: 46298 | I15: 0.75 | J15: =IF(Tasks[[#This Row],[Due]]="","",YEAR(Tasks[[#This Row],[Due]])) -> 2026
A16: T-015 | B16: Quote follow-up calls | C16: Casey L. | D16: Sales | E16: Not started | F16: High | G16: 46295 | H16: 46299 | I16: 0 | J16: =IF(Tasks[[#This Row],[Due]]="","",YEAR(Tasks[[#This Row],[Due]])) -> 2026
A17: T-016 | B17: Laptop refresh order | C17: Riley P. | D17: IT | E17: In progress | F17: Medium | G17: 46285 | H17: 46300 | I17: 0.55 | J17: =IF(Tasks[[#This Row],[Due]]="","",YEAR(Tasks[[#This Row],[Due]])) -> 2026
A18: T-017 | B18: Benefits enrollment memo | C18: Morgan T. | D18: HR | E18: In progress | F18: High | G18: 46289 | H18: 46302 | I18: 0.35 | J18: =IF(Tasks[[#This Row],[Due]]="","",YEAR(Tasks[[#This Row],[Due]])) -> 2026
A19: T-018 | B19: Fleet insurance renewal | C19: Taylor R. | D19: Operations | E19: Not started | F19: High | G19: 46296 | H19: 46303 | I19: 0 | J19: =IF(Tasks[[#This Row],[Due]]="","",YEAR(Tasks[[#This Row],[Due]])) -> 2026
A20: T-019 | B20: Monthly sales report | C20: Casey L. | D20: Sales | E20: Done | F20: Medium | G20: 46287 | H20: 46299 | I20: 1 | J20: =IF(Tasks[[#This Row],[Due]]="","",YEAR(Tasks[[#This Row],[Due]])) -> 2026 | K20: Finished early
A21: T-020 | B21: Budget draft for 2027 | C21: Jordan M. | D21: Finance | E21: In progress | F21: High | G21: 46283 | H21: 46304 | I21: 0.45 | J21: =IF(Tasks[[#This Row],[Due]]="","",YEAR(Tasks[[#This Row],[Due]])) -> 2026
A22: T-021 | B22: Website contact form fix | C22: Riley P. | D22: IT | E22: Not started | F22: Medium | G22: 46297 | H22: 46305 | I22: 0 | J22: =IF(Tasks[[#This Row],[Due]]="","",YEAR(Tasks[[#This Row],[Due]])) -> 2026
A23: T-022 | B23: Holiday schedule posting | C23: Morgan T. | D23: HR | E23: Not started | F23: Low | G23: 46298 | H23: 46306 | I23: 0 | J23: =IF(Tasks[[#This Row],[Due]]="","",YEAR(Tasks[[#This Row],[Due]])) -> 2026
A24: T-023 | B24: Dock door repair | C24: Avery K. | D24: Operations | E24: Blocked | F24: High | G24: 46292 | H24: 46307 | I24: 0.2 | J24: =IF(Tasks[[#This Row],[Due]]="","",YEAR(Tasks[[#This Row],[Due]])) -> 2026 | K24: Part on order
A25: T-024 | B25: Key account review | C25: Casey L. | D25: Sales | E25: In progress | F25: High | G25: 46294 | H25: 46309 | I25: 0.25 | J25: =IF(Tasks[[#This Row],[Due]]="","",YEAR(Tasks[[#This Row],[Due]])) -> 2026
A26: T-025 | B26: Supplier scorecards | C26: Taylor R. | D26: Operations | E26: In progress | F26: Medium | G26: 46287 | H26: 46310 | I26: 0.4 | J26: =IF(Tasks[[#This Row],[Due]]="","",YEAR(Tasks[[#This Row],[Due]])) -> 2026
A27: T-026 | B27: Password policy rollout | C27: Riley P. | D27: IT | E27: In progress | F27: High | G27: 46290 | H27: 46313 | I27: 0.3 | J27: =IF(Tasks[[#This Row],[Due]]="","",YEAR(Tasks[[#This Row],[Due]])) -> 2026
A28: T-027 | B28: Collections call list | C28: Jordan M. | D28: Finance | E28: Not started | F28: Medium | G28: 46300 | H28: 46315 | I28: 0 | J28: =IF(Tasks[[#This Row],[Due]]="","",YEAR(Tasks[[#This Row],[Due]])) -> 2026
A29: T-028 | B29: Performance review forms | C29: Morgan T. | D29: HR | E29: In progress | F29: Medium | G29: 46293 | H29: 46318 | I29: 0.15 | J29: =IF(Tasks[[#This Row],[Due]]="","",YEAR(Tasks[[#This Row],[Due]])) -> 2026
A30: T-029 | B30: Year-end inventory count | C30: Avery K. | D30: Operations | E30: Not started | F30: High | G30: 46317 | H30: 46324 | I30: 0 | J30: =IF(Tasks[[#This Row],[Due]]="","",YEAR(Tasks[[#This Row],[Due]])) -> 2026
A31: T-030 | B31: Holiday promo flyer | C31: Casey L. | D31: Sales | E31: In progress | F31: Medium | G31: 46295 | H31: 46327 | I31: 0.2 | J31: =IF(Tasks[[#This Row],[Due]]="","",YEAR(Tasks[[#This Row],[Due]])) -> 2026
A32: T-031 | B32: Phone system upgrade | C32: Riley P. | D32: IT | E32: Blocked | F32: Medium | G32: 46282 | H32: 46332 | I32: 0.1 | J32: =IF(Tasks[[#This Row],[Due]]="","",YEAR(Tasks[[#This Row],[Due]])) -> 2026 | K32: Carrier quote pending
A33: T-032 | B33: Year-end document binder | C33: Jordan M. | D33: Finance | E33: Not started | F33: High | G33: 46307 | H33: 46339 | I33: 0 | J33: =IF(Tasks[[#This Row],[Due]]="","",YEAR(Tasks[[#This Row],[Due]])) -> 2026
A34: T-033 | B34: First-aid kit restock | C34: Morgan T. | D34: HR | E34: Done | F34: Low | G34: 46285 | H34: 46311 | I34: 1 | J34: =IF(Tasks[[#This Row],[Due]]="","",YEAR(Tasks[[#This Row],[Due]])) -> 2026
A35: T-034 | B35: Delivery route review | C35: Avery K. | D35: Operations | E35: In progress | F35: Medium | G35: 46291 | H35: 46345 | I35: 0.1 | J35: =IF(Tasks[[#This Row],[Due]]="","",YEAR(Tasks[[#This Row],[Due]])) -> 2026
A36: T-035 | B36: CRM cleanup | C36: Casey L. | D36: Sales | E36: Not started | F36: Low | G36: 46311 | H36: 46353 | I36: 0 | J36: =IF(Tasks[[#This Row],[Due]]="","",YEAR(Tasks[[#This Row],[Due]])) -> 2026
A37: T-036 | B37: Office wifi upgrade | C37: Riley P. | D37: IT | E37: Done | F37: Medium | G37: 46262 | H37: 46279 | I37: 1 | J37: =IF(Tasks[[#This Row],[Due]]="","",YEAR(Tasks[[#This Row],[Due]])) -> 2026
A38: T-037 | B38: Quarterly vendor review | C38: Jordan M. | D38: Finance | E38: Done | F38: High | G38: 46277 | H38: 46292 | I38: 1 | J38: =IF(Tasks[[#This Row],[Due]]="","",YEAR(Tasks[[#This Row],[Due]])) -> 2026
A39: T-038 | B39: New-year filing setup | C39: Jordan M. | D39: Finance | E39: Not started | F39: High | G39: 46357 | H39: 46392 | I39: 0 | J39: =IF(Tasks[[#This Row],[Due]]="","",YEAR(Tasks[[#This Row],[Due]])) -> 2027
A40: T-039 | B40: Server room cleanup | C40: Riley P. | D40: IT | E40: Not started | F40: Low | G40: 46367 | H40: 46397 | I40: 0 | J40: =IF(Tasks[[#This Row],[Due]]="","",YEAR(Tasks[[#This Row],[Due]])) -> 2027
...

Sheet How to use
B2: How to use this tracker
C3: Demo built with made-up sample data. Every task and name here is invented.
B5: Add or change tasks
B6: 1 | C6: Go to the Tasks sheet and type in the first empty row under the table. The table grows by itself.
B7: 2 | C7: Status and Priority are dropdowns. % Complete takes 0% to 100%. Year fills itself in from the Due date.
B8: 3 | C8: To remove a task, right-click its row in the table and choose Delete > Table Rows.
B10: Read the dashboard
B11: 4 | C11: Pick an Owner, a Status or a Year in the yellow cells at the top. Everything on the page follows. Choose (All) to clear.
B12: 5 | C12: Overdue = not Done and the Due date is before today. Due this week = not Done and due today or in the next 6 days.
B13: 6 | C13: This Week's Focus shows up to 8 tasks, Next due dates 5, Tasks in view 15. A line under each list says how many more are not shown.
B14: 7 | C14: In the Tasks sheet, an overdue Due date turns red and one due this week turns amber, by themselves, every day.
B16: Good to know
B17: 8 | C17: Nothing here needs macros. The file works in Excel 2010 and later, including Microsoft 365.
B18: 9 | C18: The Lists sheet holds helper formulas for the dashboard. Leave it as it is.
B19: 10 | C19: The sample dates were set on Oct 2, 2026, so some tasks were overdue and some due that week. The dashboard always compares with today's date, so the counts move as days pass.

Sheet Lists
A1: Helper lists for the Dashboard. These are formulas: please don't type on this sheet.
A2: Dropdown choices on the left; on the right, which table row each dashboard list line shows.
A3: Owner choices | C3: Status choices | E3: Year choices | G3: # | H3: This Week's Focus: key | I3: Table row | K3: # | L3: Next due: key | M3: Table row | O3: # | P3: Tasks in view: key | Q3: Table row
A4: (All) | C4: (All) | E4: (All) | G4: 1 | H4: =IFERROR(_xlfn.AGGREGATE(15,6,SortKey/CondFocus,$G4),"") -> 46297 | I4: =IF(H4="","",ROUND(MOD(H4,1)*100000,0)) -> 13 | K4: 1 | L4: =IFERROR(_xlfn.AGGREGATE(15,6,SortKey/CondUpcoming,$K4),"") -> 46297 | M4: =IF(L4="","",ROUND(MOD(L4,1)*100000,0)) -> 13 | O4: 1 | P4: =IFERROR(_xlfn.AGGREGATE(15,6,SortKeyView/InScope,$O4),"") -> 46282 | Q4: =IF(P4="","",ROUND(MOD(P4,1)*100000,0)) -> 12
A5: =IFERROR(INDEX(Tasks[Owner],MATCH(_xlfn.AGGREGATE(15,6,OwnerRank/(COUNTIF(A$4:A4,Tasks[Owner])=0)/(Tasks[Owner]<>""),1),OwnerRank,0)),"") -> Avery K. | C5: Not started | E5: =IFERROR(_xlfn.AGGREGATE(15,6,Tasks[Year]/(COUNTIF(E$4:E4,Tasks[Year])=0),1),"") -> 2026 | G5: 2 | H5: =IFERROR(_xlfn.AGGREGATE(15,6,SortKey/CondFocus,$G5),"") -> 46298 | I5: =IF(H5="","",ROUND(MOD(H5,1)*100000,0)) -> 14 | K5: 2 | L5: =IFERROR(_xlfn.AGGREGATE(15,6,SortKey/CondUpcoming,$K5),"") -> 46298 | M5: =IF(L5="","",ROUND(MOD(L5,1)*100000,0)) -> 14 | O5: 2 | P5: =IFERROR(_xlfn.AGGREGATE(15,6,SortKeyView/InScope,$O5),"") -> 46285 | Q5: =IF(P5="","",ROUND(MOD(P5,1)*100000,0)) -> 6
A6: =IFERROR(INDEX(Tasks[Owner],MATCH(_xlfn.AGGREGATE(15,6,OwnerRank/(COUNTIF(A$4:A5,Tasks[Owner])=0)/(Tasks[Owner]<>""),1),OwnerRank,0)),"") -> Casey L. | C6: In progress | E6: =IFERROR(_xlfn.AGGREGATE(15,6,Tasks[Year]/(COUNTIF(E$4:E5,Tasks[Year])=0),1),"") -> 2027 | G6: 3 | H6: =IFERROR(_xlfn.AGGREGATE(15,6,SortKey/CondFocus,$G6),"") -> 46299 | I6: =IF(H6="","",ROUND(MOD(H6,1)*100000,0)) -> 15 | K6: 3 | L6: =IFERROR(_xlfn.AGGREGATE(15,6,SortKey/CondUpcoming,$K6),"") -> 46299 | M6: =IF(L6="","",ROUND(MOD(L6,1)*100000,0)) -> 15 | O6: 3 | P6: =IFERROR(_xlfn.AGGREGATE(15,6,SortKeyView/InScope,$O6),"") -> 46289 | Q6: =IF(P6="","",ROUND(MOD(P6,1)*100000,0)) -> 7
A7: =IFERROR(INDEX(Tasks[Owner],MATCH(_xlfn.AGGREGATE(15,6,OwnerRank/(COUNTIF(A$4:A6,Tasks[Owner])=0)/(Tasks[Owner]<>""),1),OwnerRank,0)),"") -> Jordan M. | C7: Blocked | E7: =IFERROR(_xlfn.AGGREGATE(15,6,Tasks[Year]/(COUNTIF(E$4:E6,Tasks[Year])=0),1),"") | G7: 4 | H7: =IFERROR(_xlfn.AGGREGATE(15,6,SortKey/CondFocus,$G7),"") -> 46300 | I7: =IF(H7="","",ROUND(MOD(H7,1)*100000,0)) -> 16 | K7: 4 | L7: =IFERROR(_xlfn.AGGREGATE(15,6,SortKey/CondUpcoming,$K7),"") -> 46300 | M7: =IF(L7="","",ROUND(MOD(L7,1)*100000,0)) -> 16 | O7: 4 | P7: =IFERROR(_xlfn.AGGREGATE(15,6,SortKeyView/InScope,$O7),"") -> 46291 | Q7: =IF(P7="","",ROUND(MOD(P7,1)*100000,0)) -> 8
A8: =IFERROR(INDEX(Tasks[Owner],MATCH(_xlfn.AGGREGATE(15,6,OwnerRank/(COUNTIF(A$4:A7,Tasks[Owner])=0)/(Tasks[Owner]<>""),1),OwnerRank,0)),"") -> Morgan T. | C8: Done | E8: =IFERROR(_xlfn.AGGREGATE(15,6,Tasks[Year]/(COUNTIF(E$4:E7,Tasks[Year])=0),1),"") | G8: 5 | H8: =IFERROR(_xlfn.AGGREGATE(15,6,SortKey/CondFocus,$G8),"") -> 46302 | I8: =IF(H8="","",ROUND(MOD(H8,1)*100000,0)) -> 17 | K8: 5 | L8: =IFERROR(_xlfn.AGGREGATE(15,6,SortKey/CondUpcoming,$K8),"") -> 46302 | M8: =IF(L8="","",ROUND(MOD(L8,1)*100000,0)) -> 17 | O8: 5 | P8: =IFERROR(_xlfn.AGGREGATE(15,6,SortKeyView/InScope,$O8),"") -> 46293 | Q8: =IF(P8="","",ROUND(MOD(P8,1)*100000,0)) -> 9
A9: =IFERROR(INDEX(Tasks[Owner],MATCH(_xlfn.AGGREGATE(15,6,OwnerRank/(COUNTIF(A$4:A8,Tasks[Owner])=0)/(Tasks[Owner]<>""),1),OwnerRank,0)),"") -> Riley P. | E9: =IFERROR(_xlfn.AGGREGATE(15,6,Tasks[Year]/(COUNTIF(E$4:E8,Tasks[Year])=0),1),"") | G9: 6 | H9: =IFERROR(_xlfn.AGGREGATE(15,6,SortKey/CondFocus,$G9),"") -> 46303 | I9: =IF(H9="","",ROUND(MOD(H9,1)*100000,0)) -> 18 | O9: 6 | P9: =IFERROR(_xlfn.AGGREGATE(15,6,SortKeyView/InScope,$O9),"") -> 46295 | Q9: =IF(P9="","",ROUND(MOD(P9,1)*100000,0)) -> 10
A10: =IFERROR(INDEX(Tasks[Owner],MATCH(_xlfn.AGGREGATE(15,6,OwnerRank/(COUNTIF(A$4:A9,Tasks[Owner])=0)/(Tasks[Owner]<>""),1),OwnerRank,0)),"") -> Taylor R. | E10: =IFERROR(_xlfn.AGGREGATE(15,6,Tasks[Year]/(COUNTIF(E$4:E9,Tasks[Year])=0),1),"") | G10: 7 | H10: =IFERROR(_xlfn.AGGREGATE(15,6,SortKey/CondFocus,$G10),"") | I10: =IF(H10="","",ROUND(MOD(H10,1)*100000,0)) | O10: 7 | P10: =IFERROR(_xlfn.AGGREGATE(15,6,SortKeyView/InScope,$O10),"") -> 46296 | Q10: =IF(P10="","",ROUND(MOD(P10,1)*100000,0)) -> 11
A11: =IFERROR(INDEX(Tasks[Owner],MATCH(_xlfn.AGGREGATE(15,6,OwnerRank/(COUNTIF(A$4:A10,Tasks[Owner])=0)/(Tasks[Owner]<>""),1),OwnerRank,0)),"") | E11: =IFERROR(_xlfn.AGGREGATE(15,6,Tasks[Year]/(COUNTIF(E$4:E10,Tasks[Year])=0),1),"") | G11: 8 | H11: =IFERROR(_xlfn.AGGREGATE(15,6,SortKey/CondFocus,$G11),"") | I11: =IF(H11="","",ROUND(MOD(H11,1)*100000,0)) | O11: 8 | P11: =IFERROR(_xlfn.AGGREGATE(15,6,SortKeyView/InScope,$O11),"") -> 46297 | Q11: =IF(P11="","",ROUND(MOD(P11,1)*100000,0)) -> 13
A12: =IFERROR(INDEX(Tasks[Owner],MATCH(_xlfn.AGGREGATE(15,6,OwnerRank/(COUNTIF(A$4:A11,Tasks[Owner])=0)/(Tasks[Owner]<>""),1),OwnerRank,0)),"") | E12: =IFERROR(_xlfn.AGGREGATE(15,6,Tasks[Year]/(COUNTIF(E$4:E11,Tasks[Year])=0),1),"") | O12: 9 | P12: =IFERROR(_xlfn.AGGREGATE(15,6,SortKeyView/InScope,$O12),"") -> 46298 | Q12: =IF(P12="","",ROUND(MOD(P12,1)*100000,0)) -> 14
A13: =IFERROR(INDEX(Tasks[Owner],MATCH(_xlfn.AGGREGATE(15,6,OwnerRank/(COUNTIF(A$4:A12,Tasks[Owner])=0)/(Tasks[Owner]<>""),1),OwnerRank,0)),"") | E13: =IFERROR(_xlfn.AGGREGATE(15,6,Tasks[Year]/(COUNTIF(E$4:E12,Tasks[Year])=0),1),"") | O13: 10 | P13: =IFERROR(_xlfn.AGGREGATE(15,6,SortKeyView/InScope,$O13),"") -> 46299 | Q13: =IF(P13="","",ROUND(MOD(P13,1)*100000,0)) -> 15
A14: =IFERROR(INDEX(Tasks[Owner],MATCH(_xlfn.AGGREGATE(15,6,OwnerRank/(COUNTIF(A$4:A13,Tasks[Owner])=0)/(Tasks[Owner]<>""),1),OwnerRank,0)),"") | E14: =IFERROR(_xlfn.AGGREGATE(15,6,Tasks[Year]/(COUNTIF(E$4:E13,Tasks[Year])=0),1),"") | O14: 11 | P14: =IFERROR(_xlfn.AGGREGATE(15,6,SortKeyView/InScope,$O14),"") -> 46300 | Q14: =IF(P14="","",ROUND(MOD(P14,1)*100000,0)) -> 16
A15: =IFERROR(INDEX(Tasks[Owner],MATCH(_xlfn.AGGREGATE(15,6,OwnerRank/(COUNTIF(A$4:A14,Tasks[Owner])=0)/(Tasks[Owner]<>""),1),OwnerRank,0)),"") | O15: 12 | P15: =IFERROR(_xlfn.AGGREGATE(15,6,SortKeyView/InScope,$O15),"") -> 46302 | Q15: =IF(P15="","",ROUND(MOD(P15,1)*100000,0)) -> 17
A16: =IFERROR(INDEX(Tasks[Owner],MATCH(_xlfn.AGGREGATE(15,6,OwnerRank/(COUNTIF(A$4:A15,Tasks[Owner])=0)/(Tasks[Owner]<>""),1),OwnerRank,0)),"") | O16: 13 | P16: =IFERROR(_xlfn.AGGREGATE(15,6,SortKeyView/InScope,$O16),"") -> 46303 | Q16: =IF(P16="","",ROUND(MOD(P16,1)*100000,0)) -> 18
A17: =IFERROR(INDEX(Tasks[Owner],MATCH(_xlfn.AGGREGATE(15,6,OwnerRank/(COUNTIF(A$4:A16,Tasks[Owner])=0)/(Tasks[Owner]<>""),1),OwnerRank,0)),"") | O17: 14 | P17: =IFERROR(_xlfn.AGGREGATE(15,6,SortKeyView/InScope,$O17),"") -> 46304 | Q17: =IF(P17="","",ROUND(MOD(P17,1)*100000,0)) -> 20
A18: =IFERROR(INDEX(Tasks[Owner],MATCH(_xlfn.AGGREGATE(15,6,OwnerRank/(COUNTIF(A$4:A17,Tasks[Owner])=0)/(Tasks[Owner]<>""),1),OwnerRank,0)),"") | O18: 15 | P18: =IFERROR(_xlfn.AGGREGATE(15,6,SortKeyView/InScope,$O18),"") -> 46305 | Q18: =IF(P18="","",ROUND(MOD(P18,1)*100000,0)) -> 21
A19: =IFERROR(INDEX(Tasks[Owner],MATCH(_xlfn.AGGREGATE(15,6,OwnerRank/(COUNTIF(A$4:A18,Tasks[Owner])=0)/(Tasks[Owner]<>""),1),OwnerRank,0)),"")
A20: =IFERROR(INDEX(Tasks[Owner],MATCH(_xlfn.AGGREGATE(15,6,OwnerRank/(COUNTIF(A$4:A19,Tasks[Owner])=0)/(Tasks[Owner]<>""),1),OwnerRank,0)),"")
A21: =IFERROR(INDEX(Tasks[Owner],MATCH(_xlfn.AGGREGATE(15,6,OwnerRank/(COUNTIF(A$4:A20,Tasks[Owner])=0)/(Tasks[Owner]<>""),1),OwnerRank,0)),"")
A22: =IFERROR(INDEX(Tasks[Owner],MATCH(_xlfn.AGGREGATE(15,6,OwnerRank/(COUNTIF(A$4:A21,Tasks[Owner])=0)/(Tasks[Owner]<>""),1),OwnerRank,0)),"")
A23: =IFERROR(INDEX(Tasks[Owner],MATCH(_xlfn.AGGREGATE(15,6,OwnerRank/(COUNTIF(A$4:A22,Tasks[Owner])=0)/(Tasks[Owner]<>""),1),OwnerRank,0)),"")
A24: =IFERROR(INDEX(Tasks[Owner],MATCH(_xlfn.AGGREGATE(15,6,OwnerRank/(COUNTIF(A$4:A23,Tasks[Owner])=0)/(Tasks[Owner]<>""),1),OwnerRank,0)),"")
A25: =IFERROR(INDEX(Tasks[Owner],MATCH(_xlfn.AGGREGATE(15,6,OwnerRank/(COUNTIF(A$4:A24,Tasks[Owner])=0)/(Tasks[Owner]<>""),1),OwnerRank,0)),"")
A26: =IFERROR(INDEX(Tasks[Owner],MATCH(_xlfn.AGGREGATE(15,6,OwnerRank/(COUNTIF(A$4:A25,Tasks[Owner])=0)/(Tasks[Owner]<>""),1),OwnerRank,0)),"")
A27: =IFERROR(INDEX(Tasks[Owner],MATCH(_xlfn.AGGREGATE(15,6,OwnerRank/(COUNTIF(A$4:A26,Tasks[Owner])=0)/(Tasks[Owner]<>""),1),OwnerRank,0)),"")
A28: =IFERROR(INDEX(Tasks[Owner],MATCH(_xlfn.AGGREGATE(15,6,OwnerRank/(COUNTIF(A$4:A27,Tasks[Owner])=0)/(Tasks[Owner]<>""),1),OwnerRank,0)),"")
A29: =IFERROR(INDEX(Tasks[Owner],MATCH(_xlfn.AGGREGATE(15,6,OwnerRank/(COUNTIF(A$4:A28,Tasks[Owner])=0)/(Tasks[Owner]<>""),1),OwnerRank,0)),"")
A30: =IFERROR(INDEX(Tasks[Owner],MATCH(_xlfn.AGGREGATE(15,6,OwnerRank/(COUNTIF(A$4:A29,Tasks[Owner])=0)/(Tasks[Owner]<>""),1),OwnerRank,0)),"")
... A34: =IFERROR(INDEX(Tasks[Owner],MATCH(_xlfn.AGGREGATE(15,6,OwnerRank/(COUNTIF(A$4:A33,Tasks[Owner])=0)/(Tasks[Owner]<>""),1),OwnerRank,0)),"")
